2022-04-30 19:21:04,061 INFO    BackendThr:49927 [internal.py:wandb_internal():93] W&B internal server running at pid: 49927, started at: 2022-04-30 19:21:04.058641
2022-04-30 19:21:04,072 INFO    MainThread:49927 [wandb_init.py:init():597] updated telemetry
2022-04-30 19:21:04,075 DEBUG   SenderThread:49927 [sender.py:send():232] send: header
2022-04-30 19:21:04,076 INFO    WriterThread:49927 [datastore.py:open_for_write():75] open: /home/home01/sclaam/spase-resnet-50-experiments/outputs/CIFAR10/RigL/0.05/++dataset.max_threads=1,++optimizer.epochs=10,+specific=cifar10_wrn_22_2_rigL_modified/wandb/run-20220430_192104-1kj1q80v/run-1kj1q80v.wandb
2022-04-30 19:21:04,124 INFO    MainThread:49927 [wandb_init.py:init():628] communicating run to backend with 30 second timeout
2022-04-30 19:21:04,126 DEBUG   SenderThread:49927 [sender.py:send():232] send: run
2022-04-30 19:21:34,126 INFO    MainThread:49927 [interface_shared.py:_communicate_run():326] couldn't get run from backend
2022-04-30 19:21:34,127 ERROR   MainThread:49927 [wandb_init.py:init():633] backend process timed out
2022-04-30 19:21:34,127 ERROR   MainThread:49927 [wandb_init.py:init():644] encountered error: Error communicating with wandb process
try: wandb.init(settings=wandb.Settings(start_method='fork'))
or:  wandb.init(settings=wandb.Settings(start_method='thread'))
For more info see: https://docs.wandb.ai/library/init#init-start-error
2022-04-30 19:21:34,128 DEBUG   HandlerThread:49927 [handler.py:handle_request():141] handle_request: shutdown
2022-04-30 19:21:34,128 INFO    HandlerThread:49927 [handler.py:finish():806] shutting down handler
2022-04-30 19:21:34,132 INFO    WriterThread:49927 [datastore.py:close():279] close: /home/home01/sclaam/spase-resnet-50-experiments/outputs/CIFAR10/RigL/0.05/++dataset.max_threads=1,++optimizer.epochs=10,+specific=cifar10_wrn_22_2_rigL_modified/wandb/run-20220430_192104-1kj1q80v/run-1kj1q80v.wandb
2022-04-30 19:21:34,159 ERROR   SenderThread:49927 [internal_api.py:execute():143] 409 response executing GraphQL.
2022-04-30 19:21:34,159 ERROR   SenderThread:49927 [internal_api.py:execute():144] {"errors":[{"message":"Error 1062: Duplicate entry '855911-1kj1q80v' for key 'PRIMARY'","path":["upsertBucket"]}],"data":{"upsertBucket":null}}
2022-04-30 19:21:35,098 ERROR   BackendThr:49927 [internal.py:wandb_internal():165] Thread SenderThread:
Traceback (most recent call last):
  File "/home/home01/sclaam/.local/lib/python3.7/site-packages/wandb/apis/normalize.py", line 22, in wrapper
    return func(*args, **kwargs)
  File "/home/home01/sclaam/.local/lib/python3.7/site-packages/wandb/sdk/internal/internal_api.py", line 1318, in upsert_run
    response = self.gql(mutation, variable_values=variable_values, **kwargs)
  File "/home/home01/sclaam/.local/lib/python3.7/site-packages/wandb/sdk/lib/retry.py", line 102, in __call__
    result = self._call_fn(*args, **kwargs)
  File "/home/home01/sclaam/.local/lib/python3.7/site-packages/wandb/sdk/internal/internal_api.py", line 140, in execute
    return self.client.execute(*args, **kwargs)
  File "/home/home01/sclaam/.local/lib/python3.7/site-packages/wandb/vendor/gql-0.2.0/wandb_gql/client.py", line 52, in execute
    result = self._get_result(document, *args, **kwargs)
  File "/home/home01/sclaam/.local/lib/python3.7/site-packages/wandb/vendor/gql-0.2.0/wandb_gql/client.py", line 60, in _get_result
    return self.transport.execute(document, *args, **kwargs)
  File "/home/home01/sclaam/.local/lib/python3.7/site-packages/wandb/vendor/gql-0.2.0/wandb_gql/transport/requests.py", line 39, in execute
    request.raise_for_status()
  File "/apps/developers/compilers/anaconda/2019.10/1/default/lib/python3.7/site-packages/requests/models.py", line 940, in raise_for_status
    raise HTTPError(http_error_msg, response=self)
requests.exceptions.HTTPError: 409 Client Error: Conflict for url: https://api.wandb.ai/graphql

During handling of the above exception, another exception occurred:

Traceback (most recent call last):
  File "/home/home01/sclaam/.local/lib/python3.7/site-packages/wandb/sdk/internal/internal_util.py", line 51, in run
    self._run()
  File "/home/home01/sclaam/.local/lib/python3.7/site-packages/wandb/sdk/internal/internal_util.py", line 102, in _run
    self._process(record)
  File "/home/home01/sclaam/.local/lib/python3.7/site-packages/wandb/sdk/internal/internal.py", line 310, in _process
    self._sm.send(record)
  File "/home/home01/sclaam/.local/lib/python3.7/site-packages/wandb/sdk/internal/sender.py", line 234, in send
    send_handler(record)
  File "/home/home01/sclaam/.local/lib/python3.7/site-packages/wandb/sdk/internal/sender.py", line 692, in send_run
    self._init_run(run, config_value_dict)
  File "/home/home01/sclaam/.local/lib/python3.7/site-packages/wandb/sdk/internal/sender.py", line 730, in _init_run
    commit=run.git.last_commit or None,
  File "/home/home01/sclaam/.local/lib/python3.7/site-packages/wandb/apis/normalize.py", line 24, in wrapper
    raise CommError(err.response, err)
wandb.errors.CommError: <Response [409]>
2022-04-30 19:21:37,214 INFO    MainThread:49927 [wandb_init.py:teardown():285] tearing down wandb.init
2022-04-30 19:21:37,562 INFO    MainThread:49927 [internal.py:handle_exit():80] Internal process exited
